[root at 2023-02-23 14:10:39,465]: Archipelago (0.3.9) logging initialized on Linux-6.1.12-x64v3-xanmod1-x86_64-with-glibc2.35 running Python 3.10.6
[root at 2023-02-23 14:10:39,488]: Uncaught exception
Traceback (most recent call last):
  File "/mnt/115b93af-9f3b-43c4-a778-48dcab29caf0/Randomizers/Archipelago Betas/Generate.py", line 643, in <module>
    main()
  File "/mnt/115b93af-9f3b-43c4-a778-48dcab29caf0/Randomizers/Archipelago Betas/Generate.py", line 202, in main
    raise Exception(f"Names have to be unique. Names: {Counter(name.lower() for name in erargs.name.values())}")
Exception: Names have to be unique. Names: Counter({'riskofkiller': 2, 'killermuse': 2, 'bluejello-time': 1, 'boris_bla': 1, 'boris_bla2': 1, 'boris_bla3': 1, 'felthepenitent': 1, 'fel_kh2': 1, 'fel_ut': 1, 'fuzzymess': 1, 'fuzzyunder': 1, 'glaceon': 1, 'graykh2': 1, 'grayksa2': 1, 'mewlifffps': 1, 'mewlifut': 1, 'myranda (blimbu)': 1, 'myranda (dubonk)': 1, 'myranda (ringo)': 1, 'radz_ladx': 1, 'risk4cake': 1, 'bluejello-ror': 1, 'squidy25': 1, 'samwizest1': 1, 'terrabulllttp': 1, 'terrabullmd': 1, 'bluejello-war': 1, 'mrpokemon11war': 1, 'mrpokemon11btnss': 1, 'mrpokemon11tsbta': 1, 'squidy33': 1})
